Autotested Results for N/A submitted by 
Generated at N/A

Summary of Results: 5 out of 6 tests successfully passed
--

Tests for create_tests.CreatefileTest (1/2 passed)
--

1) create_tests.CreatefileTest.test_nofentry                                          .. ok!
2) create_tests.CreatefileTest.test_emptyfs                                           .. failed
.. because False is not true (details below):

    Traceback (most recent call last):

      File "/usr/lib/python3.6/unittest/case.py", line 59, in testPartExecutor
        yield

      File "/usr/lib/python3.6/unittest/case.py", line 605, in run
        testMethod()

      File "/res/peters43/209/huang853/a2/test_helpers.py", line 243, in _t
        self.assertTrue(_diff_files(outputname, solname, start, len))

      File "/usr/lib/python3.6/unittest/case.py", line 682, in assertTrue
        raise self.failureException(msg)

    AssertionError: False is not true




Tests for read_tests.ReadfileTest (2/2 passed)
--

1) read_tests.ReadfileTest.test_firstfile_start0_lessthanblocksize                    .. ok!
2) read_tests.ReadfileTest.test_firstfile_start4_morethanblocksize                    .. ok!


Tests for write_tests.WritefileTest (2/2 passed)
--

1) write_tests.WritefileTest.test_size0_lessthanblocksize                             .. ok!
2) write_tests.WritefileTest.test_size2_morethanblocksize                             .. ok!


