Autotested Results for A3 submitted by YE HUANG (huang853)
Generated at 2020-03-13T23:50:33

Summary of Results: 30 out of 36 tests successfully passed
--

Tests for bruteforce.BruteforceTest (4/4 passed)
--

1) bruteforce.BruteforceTest.test_32_element_list                                     .. ok!
2) bruteforce.BruteforceTest.test_duplicate_points                                    .. ok!
3) bruteforce.BruteforceTest.test_short_even_list                                     .. ok!
4) bruteforce.BruteforceTest.test_short_odd_list                                      .. ok!


Tests for overflow.OverflowTest (1/1 passed)
--

1) overflow.OverflowTest.test_overlow                                                 .. ok!


Tests for serial.SerialTest (6/7 passed)
--

1) serial.SerialTest.test_32_element_list                                             .. ok!
2) serial.SerialTest.test_duplicate_points                                            .. ok!
3) serial.SerialTest.test_is_recursive                                                .. ok!
4) serial.SerialTest.test_large_list_one                                              .. ok!
5) serial.SerialTest.test_large_list_three                                            .. ok!
6) serial.SerialTest.test_large_list_two                                              .. ok!
7) serial.SerialTest.test_33_element_list                                             .. failed
.. because 1 != 0 (details below):

    Traceback (most recent call last):

      File "/usr/lib/python3.6/unittest/case.py", line 59, in testPartExecutor
        yield

      File "/usr/lib/python3.6/unittest/case.py", line 605, in run
        testMethod()

      File "/res/peters43/209/huang853/a3/test_helpers.py", line 196, in _t
        self.assertEqual(returncode, expected_status)

      File "/usr/lib/python3.6/unittest/case.py", line 829, in assertEqual
        assertion_func(first, second, msg=msg)

      File "/usr/lib/python3.6/unittest/case.py", line 822, in _baseAssertEqual
        raise self.failureException(msg)

    AssertionError: 1 != 0




Tests for parallel.ParallelTest (5/9 passed)
--

1) parallel.ParallelTest.test_32_element_list                                         .. ok!
2) parallel.ParallelTest.test_duplicate_points                                        .. ok!
3) parallel.ParallelTest.test_large_list_one                                          .. ok!
4) parallel.ParallelTest.test_large_list_three                                        .. ok!
5) parallel.ParallelTest.test_large_list_two                                          .. ok!
6) parallel.ParallelTest.test_33_element_list                                         .. failed
.. because 1 != 0 (details below):

    Traceback (most recent call last):

      File "/usr/lib/python3.6/unittest/case.py", line 59, in testPartExecutor
        yield

      File "/usr/lib/python3.6/unittest/case.py", line 605, in run
        testMethod()

      File "/res/peters43/209/huang853/a3/test_helpers.py", line 196, in _t
        self.assertEqual(returncode, expected_status)

      File "/usr/lib/python3.6/unittest/case.py", line 829, in assertEqual
        assertion_func(first, second, msg=msg)

      File "/usr/lib/python3.6/unittest/case.py", line 822, in _baseAssertEqual
        raise self.failureException(msg)

    AssertionError: 1 != 0


7) parallel.ParallelTest.test_processes_32_element_list                               .. failed
.. because 1 != 0 (details below):

    Traceback (most recent call last):

      File "/usr/lib/python3.6/unittest/case.py", line 59, in testPartExecutor
        yield

      File "/usr/lib/python3.6/unittest/case.py", line 605, in run
        testMethod()

      File "/res/peters43/209/huang853/a3/test_helpers.py", line 196, in _t
        self.assertEqual(returncode, expected_status)

      File "/usr/lib/python3.6/unittest/case.py", line 829, in assertEqual
        assertion_func(first, second, msg=msg)

      File "/usr/lib/python3.6/unittest/case.py", line 822, in _baseAssertEqual
        raise self.failureException(msg)

    AssertionError: 1 != 0


8) parallel.ParallelTest.test_processes_49_element_list                               .. failed
.. because 1 != 0 (details below):

    Traceback (most recent call last):

      File "/usr/lib/python3.6/unittest/case.py", line 59, in testPartExecutor
        yield

      File "/usr/lib/python3.6/unittest/case.py", line 605, in run
        testMethod()

      File "/res/peters43/209/huang853/a3/test_helpers.py", line 196, in _t
        self.assertEqual(returncode, expected_status)

      File "/usr/lib/python3.6/unittest/case.py", line 829, in assertEqual
        assertion_func(first, second, msg=msg)

      File "/usr/lib/python3.6/unittest/case.py", line 822, in _baseAssertEqual
        raise self.failureException(msg)

    AssertionError: 1 != 0


9) parallel.ParallelTest.test_processes_large_list                                    .. failed
.. because 1 != 0 (details below):

    Traceback (most recent call last):

      File "/usr/lib/python3.6/unittest/case.py", line 59, in testPartExecutor
        yield

      File "/usr/lib/python3.6/unittest/case.py", line 605, in run
        testMethod()

      File "/res/peters43/209/huang853/a3/test_helpers.py", line 196, in _t
        self.assertEqual(returncode, expected_status)

      File "/usr/lib/python3.6/unittest/case.py", line 829, in assertEqual
        assertion_func(first, second, msg=msg)

      File "/usr/lib/python3.6/unittest/case.py", line 822, in _baseAssertEqual
        raise self.failureException(msg)

    AssertionError: 1 != 0




Tests for parallel_with_init.ParallelWithInitTest (8/9 passed)
--

1) parallel_with_init.ParallelWithInitTest.test_32_element_list                       .. ok!
2) parallel_with_init.ParallelWithInitTest.test_duplicate_points                      .. ok!
3) parallel_with_init.ParallelWithInitTest.test_large_list_one                        .. ok!
4) parallel_with_init.ParallelWithInitTest.test_large_list_three                      .. ok!
5) parallel_with_init.ParallelWithInitTest.test_large_list_two                        .. ok!
6) parallel_with_init.ParallelWithInitTest.test_processes_32_element_list             .. ok!
7) parallel_with_init.ParallelWithInitTest.test_processes_49_element_list             .. ok!
8) parallel_with_init.ParallelWithInitTest.test_processes_large_list                  .. ok!
9) parallel_with_init.ParallelWithInitTest.test_33_element_list                       .. failed
.. because 1 != 0 (details below):

    Traceback (most recent call last):

      File "/usr/lib/python3.6/unittest/case.py", line 59, in testPartExecutor
        yield

      File "/usr/lib/python3.6/unittest/case.py", line 605, in run
        testMethod()

      File "/res/peters43/209/huang853/a3/test_helpers.py", line 196, in _t
        self.assertEqual(returncode, expected_status)

      File "/usr/lib/python3.6/unittest/case.py", line 829, in assertEqual
        assertion_func(first, second, msg=msg)

      File "/usr/lib/python3.6/unittest/case.py", line 822, in _baseAssertEqual
        raise self.failureException(msg)

    AssertionError: 1 != 0




Tests for traces.CallTraceTest (6/6 passed)
--

1) traces.CallTraceTest.test_checks_mid_after_wait                                    .. ok!
2) traces.CallTraceTest.test_closes_pipe_before_wait                                  .. ok!
3) traces.CallTraceTest.test_forks_twice                                              .. ok!
4) traces.CallTraceTest.test_forks_twice_before_wait                                  .. ok!
5) traces.CallTraceTest.test_qsort_called                                             .. ok!
6) traces.CallTraceTest.test_reads_from_pipes                                         .. ok!


